<mujoco model="cube_falling">
    <option timestep="0.01" gravity="0 0 -9.81"/>
    <worldbody>
        <geom type="plane" size="5 5 0.1" rgba="0.5 0.5 0.5 1"/>
        <body name="cube2" pos="0 0 1">
            <joint name="Sphere" type="free"/>
            <geom type="sphere" size="0.1 0.1 0.1" mass="1" rgba="0 1 0 1"/>
        </body>
        <body name="cube" pos="0 0.2 1">
            <joint name="free_joint_cube" type="hinge"/>
            <geom type="box" size="0.1 0.1 0.1" mass="1" rgba="0 0 1 1"/>
        </body>
    </worldbody>

    <actuator>
        <motor joint="free_joint_cube" ctrlrange="-10 10" gear="1"/>
    </actuator>

</mujoco>
